{"uuid": "a4e14ea3-9f70-4bd6-8ae3-16befbe37837", "children": ["5cc739a4-4576-4329-a32c-5132167643ee"], "befores": [{"name": "test_setup", "status": "passed", "start": 1593969696958, "stop": 1593969702061}], "afters": [{"name": "test_setup::0", "status": "broken", "statusDetails": {"message": "selenium.common.exceptions.WebDriverException: Message: chrome not reachable\n  (Session info: chrome=83.0.4103.116)\n\n", "trace": "  File \"C:\\Users\\Dror\\AppData\\Local\\Programs\\Python\\Python38-32\\lib\\site-packages\\allure_commons\\_allure.py\", line 185, in __call__\n    return self._fixture_function(*args, **kwargs)\n  File \"C:\\Users\\Dror\\AppData\\Local\\Programs\\Python\\Python38-32\\lib\\site-packages\\_pytest\\fixtures.py\", line 800, in _teardown_yield_fixture\n    next(it)\n  File \"C:\\Users\\Dror\\Desktop\\Automation\\PythonAutomationFramework_1-master\\conftest.py\", line 23, in test_setup\n    driver.close()\n  File \"C:\\Users\\Dror\\AppData\\Local\\Programs\\Python\\Python38-32\\lib\\site-packages\\selenium\\webdriver\\remote\\webdriver.py\", line 688, in close\n    self.execute(Command.CLOSE)\n  File \"C:\\Users\\Dror\\AppData\\Local\\Programs\\Python\\Python38-32\\lib\\site-packages\\selenium\\webdriver\\remote\\webdriver.py\", line 321, in execute\n    self.error_handler.check_response(response)\n  File \"C:\\Users\\Dror\\AppData\\Local\\Programs\\Python\\Python38-32\\lib\\site-packages\\selenium\\webdriver\\remote\\errorhandler.py\", line 242, in check_response\n    raise exception_class(message, screen, stacktrace)\n"}, "start": 1593969706213, "stop": 1593969710233}], "start": 1593969696958, "stop": 1593969710233}