{"uuid": "2f15d2a4-49a2-4eef-9891-4fa888c26fb7", "children": ["ca6a2b2b-4135-431e-9535-79ddad1d4876"], "befores": [{"name": "test_setup", "status": "passed", "start": 1593971722936, "stop": 1593971728065}], "afters": [{"name": "test_setup::0", "status": "broken", "statusDetails": {"message": "selenium.common.exceptions.WebDriverException: Message: chrome not reachable\n  (Session info: chrome=83.0.4103.116)\n\n", "trace": "  File \"C:\\Users\\Dror\\AppData\\Local\\Programs\\Python\\Python38-32\\lib\\site-packages\\allure_commons\\_allure.py\", line 185, in __call__\n    return self._fixture_function(*args, **kwargs)\n  File \"C:\\Users\\Dror\\AppData\\Local\\Programs\\Python\\Python38-32\\lib\\site-packages\\_pytest\\fixtures.py\", line 800, in _teardown_yield_fixture\n    next(it)\n  File \"C:\\Users\\Dror\\Desktop\\Automation\\PythonAutomationFramework_1-master\\conftest.py\", line 23, in test_setup\n    driver.close()\n  File \"C:\\Users\\Dror\\AppData\\Local\\Programs\\Python\\Python38-32\\lib\\site-packages\\selenium\\webdriver\\remote\\webdriver.py\", line 688, in close\n    self.execute(Command.CLOSE)\n  File \"C:\\Users\\Dror\\AppData\\Local\\Programs\\Python\\Python38-32\\lib\\site-packages\\selenium\\webdriver\\remote\\webdriver.py\", line 321, in execute\n    self.error_handler.check_response(response)\n  File \"C:\\Users\\Dror\\AppData\\Local\\Programs\\Python\\Python38-32\\lib\\site-packages\\selenium\\webdriver\\remote\\errorhandler.py\", line 242, in check_response\n    raise exception_class(message, screen, stacktrace)\n"}, "start": 1593971733321, "stop": 1593971737329}], "start": 1593971722936, "stop": 1593971737329}