{"uuid": "7b50344d-97a6-408b-97f5-d21642ecea86", "children": ["087aa076-95f0-4a18-8460-b2f1c6aafbf3", "c9119576-dfb7-4bdd-bf18-3b278261b35e"], "befores": [{"name": "test_setup", "status": "broken", "statusDetails": {"message": "selenium.common.exceptions.WebDriverException: Message: 'chromedriver.exe' executable needs to be in PATH. Please see https://sites.google.com/a/chromium.org/chromedriver/home\n\n", "trace": "  File \"C:\\Users\\Dror\\AppData\\Local\\Programs\\Python\\Python38-32\\lib\\site-packages\\pluggy\\callers.py\", line 187, in _multicall\n    res = hook_impl.function(*args)\n  File \"C:\\Users\\Dror\\AppData\\Local\\Programs\\Python\\Python38-32\\lib\\site-packages\\_pytest\\fixtures.py\", line 964, in pytest_fixture_setup\n    result = call_fixture_func(fixturefunc, request, kwargs)\n  File \"C:\\Users\\Dror\\AppData\\Local\\Programs\\Python\\Python38-32\\lib\\site-packages\\_pytest\\fixtures.py\", line 788, in call_fixture_func\n    res = next(it)\n  File \"C:\\Users\\Dror\\Desktop\\Automation\\PythonAutomationFramework_1-master\\conftest.py\", line 14, in test_setup\n    driver = webdriver.Chrome(\n  File \"C:\\Users\\Dror\\AppData\\Local\\Programs\\Python\\Python38-32\\lib\\site-packages\\selenium\\webdriver\\chrome\\webdriver.py\", line 73, in __init__\n    self.service.start()\n  File \"C:\\Users\\Dror\\AppData\\Local\\Programs\\Python\\Python38-32\\lib\\site-packages\\selenium\\webdriver\\common\\service.py\", line 81, in start\n    raise WebDriverException(\n"}, "start": 1593870298448, "stop": 1593870298448}], "start": 1593870298448, "stop": 1593870298631}