{"uuid": "6efac8b5-c6b7-4ef2-9f8a-f44fc0d6ac36", "children": ["bc439f5e-e3fa-4060-95a2-5fd0f5d8958d", "df662261-4e07-4613-afab-6a1048e45bef"], "befores": [{"name": "test_setup", "status": "broken", "statusDetails": {"message": "selenium.common.exceptions.WebDriverException: Message: 'chromedriver.exe' executable needs to be in PATH. Please see https://sites.google.com/a/chromium.org/chromedriver/home\n\n", "trace": "  File \"C:\\Users\\Dror\\AppData\\Local\\Programs\\Python\\Python38-32\\lib\\site-packages\\pluggy\\callers.py\", line 187, in _multicall\n    res = hook_impl.function(*args)\n  File \"C:\\Users\\Dror\\AppData\\Local\\Programs\\Python\\Python38-32\\lib\\site-packages\\_pytest\\fixtures.py\", line 964, in pytest_fixture_setup\n    result = call_fixture_func(fixturefunc, request, kwargs)\n  File \"C:\\Users\\Dror\\AppData\\Local\\Programs\\Python\\Python38-32\\lib\\site-packages\\_pytest\\fixtures.py\", line 788, in call_fixture_func\n    res = next(it)\n  File \"C:\\Users\\Dror\\Desktop\\Automation\\PythonAutomationFramework_1-master\\conftest.py\", line 14, in test_setup\n    driver = webdriver.Chrome(\n  File \"C:\\Users\\Dror\\AppData\\Local\\Programs\\Python\\Python38-32\\lib\\site-packages\\selenium\\webdriver\\chrome\\webdriver.py\", line 73, in __init__\n    self.service.start()\n  File \"C:\\Users\\Dror\\AppData\\Local\\Programs\\Python\\Python38-32\\lib\\site-packages\\selenium\\webdriver\\common\\service.py\", line 81, in start\n    raise WebDriverException(\n"}, "start": 1593870256564, "stop": 1593870256564}], "start": 1593870256564, "stop": 1593870256782}